<?xml version="1.0"?>
<robot name="av_robot">

  <!-- ── Chassis ─────────────────────────────────────────────────── -->
  <link name="base_link">
    <visual>
      <geometry><box size="0.4 0.3 0.1"/></geometry>
      <material name="blue"><color rgba="0.2 0.4 0.8 1.0"/></material>
    </visual>
    <collision>
      <geometry><box size="0.4 0.3 0.1"/></geometry>
    </collision>
    <inertial>
      <mass value="5.0"/>
      <inertia ixx="0.035" ixy="0" ixz="0" iyy="0.068" iyz="0" izz="0.1"/>
    </inertial>
  </link>

  <!-- ── Left wheel ─────────────────────────────────────────────── -->
  <joint name="left_wheel_joint" type="continuous">
    <parent link="base_link"/>
    <child link="left_wheel"/>
    <origin xyz="0 0.17 -0.025" rpy="-1.5708 0 0"/>
    <axis xyz="0 0 1"/>
  </joint>
  <link name="left_wheel">
    <visual>
      <geometry><cylinder radius="0.1" length="0.04"/></geometry>
      <material name="dark"><color rgba="0.1 0.1 0.1 1"/></material>
    </visual>
    <collision>
      <geometry><cylinder radius="0.1" length="0.04"/></geometry>
    </collision>
    <inertial>
      <mass value="0.5"/>
      <inertia ixx="0.00125" ixy="0" ixz="0" iyy="0.00125" iyz="0" izz="0.0025"/>
    </inertial>
  </link>

  <!-- ── Right wheel ────────────────────────────────────────────── -->
  <joint name="right_wheel_joint" type="continuous">
    <parent link="base_link"/>
    <child link="right_wheel"/>
    <origin xyz="0 -0.17 -0.025" rpy="-1.5708 0 0"/>
    <axis xyz="0 0 1"/>
  </joint>
  <link name="right_wheel">
    <visual>
      <geometry><cylinder radius="0.1" length="0.04"/></geometry>
      <material name="dark"><color rgba="0.1 0.1 0.1 1"/></material>
    </visual>
    <collision>
      <geometry><cylinder radius="0.1" length="0.04"/></geometry>
    </collision>
    <inertial>
      <mass value="0.5"/>
      <inertia ixx="0.00125" ixy="0" ixz="0" iyy="0.00125" iyz="0" izz="0.0025"/>
    </inertial>
  </link>

  <!-- ── Rear caster ────────────────────────────────────────────── -->
  <joint name="caster_joint" type="fixed">
    <parent link="base_link"/>
    <child link="caster_link"/>
    <origin xyz="-0.15 0 -0.07" rpy="0 0 0"/>
  </joint>
  <link name="caster_link">
    <visual>
      <geometry><sphere radius="0.04"/></geometry>
      <material name="grey"><color rgba="0.6 0.6 0.6 1"/></material>
    </visual>
    <collision>
      <geometry><sphere radius="0.04"/></geometry>
    </collision>
    <inertial>
      <mass value="0.1"/>
      <inertia ixx="6.4e-5" ixy="0" ixz="0" iyy="6.4e-5" iyz="0" izz="6.4e-5"/>
    </inertial>
  </link>
  <gazebo reference="caster_link">
    <mu1>0.0</mu1>
    <mu2>0.0</mu2>
  </gazebo>

  <!-- ── Lidar mount ────────────────────────────────────────────── -->
  <joint name="laser_joint" type="fixed">
    <parent link="base_link"/>
    <child link="laser_link"/>
    <origin xyz="0 0 0.1" rpy="0 0 0"/>
  </joint>
  <link name="laser_link">
    <visual>
      <geometry><cylinder radius="0.03" length="0.04"/></geometry>
      <material name="black"><color rgba="0 0 0 1"/></material>
    </visual>
  </link>

  <!-- ── Gazebo: differential drive ────────────────────────────── -->
  <gazebo>
    <plugin name="diff_drive" filename="libgazebo_ros_diff_drive.so">
      <left_joint>left_wheel_joint</left_joint>
      <right_joint>right_wheel_joint</right_joint>
      <wheel_separation>0.34</wheel_separation>
      <wheel_diameter>0.2</wheel_diameter>
      <max_wheel_torque>20</max_wheel_torque>
      <max_wheel_acceleration>1.0</max_wheel_acceleration>
      <command_topic>cmd_vel</command_topic>
      <odometry_topic>odom</odometry_topic>
      <odometry_frame>odom</odometry_frame>
      <robot_base_frame>base_link</robot_base_frame>
      <publish_odom>true</publish_odom>
      <publish_odom_tf>true</publish_odom_tf>
      <publish_wheel_tf>false</publish_wheel_tf>
    </plugin>
  </gazebo>

  <!-- ── Gazebo: CPU ray sensor (no GPU off-screen rendering) ──── -->
  <gazebo reference="laser_link">
    <sensor type="ray" name="lidar">
      <always_on>true</always_on>
      <update_rate>10</update_rate>
      <visualize>false</visualize>
      <ray>
        <scan>
          <horizontal>
            <samples>180</samples>
            <resolution>1</resolution>
            <min_angle>-3.14159265</min_angle>
            <max_angle>3.14159265</max_angle>
          </horizontal>
        </scan>
        <range>
          <min>0.1</min>
          <max>8.0</max>
          <resolution>0.01</resolution>
        </range>
      </ray>
      <plugin name="lidar_plugin" filename="libgazebo_ros_ray_sensor.so">
        <ros>
          <remapping>~/out:=scan</remapping>
        </ros>
        <output_type>sensor_msgs/LaserScan</output_type>
        <frame_name>laser_link</frame_name>
      </plugin>
    </sensor>
  </gazebo>

</robot>
